```go
func main() {
    defer func() {fmt.Println("1")}
    defer func() {fmt.Println("2")}
    defer func() {fmt.Println("3")}
    panic("异常")
}
//输出顺序：
//3
//2
//1
//异常
```

defer 的执行顺序是先进后出，发生 panic 后，会先执行 defer



```go
func main() {
    outFunc()
}

func outFunc() {
    inFunc()
}

func inFunc() {
    panic(errors.New("sdads"))
}

```

这段代码的运行：<img src="http://akatsuke.com/image-20201024231602144.png" alt="image-20201024231602144" style="zoom: 67%;" />

当调用inFunc函数中的panic函数后，inFunc执行会被停止，紧接着流程的控制权会转交回调用方outFunc函数，然后，outFunc函数的执行也将被停止，运行时恐慌就这样沿着调用栈反方向进行传播，直到达到当前goroutine的调用栈的最顶层，此时，意味着goroutine调用栈中所有函数的执行都被停止了，程序崩溃。

运行时恐慌一旦引发，就会向调用方法传播直至程序崩溃，go提供了专用于“拦截”运行时恐慌的内建函数recover，它可以使当前程序从恐慌状态中恢复并且重新获得流程控制权。recover函数被调用的时候，会返回一个interface{}类型的结果，